2023-04-19 09:46:05,444 INFO    Thread-264 (_run_job):16112 [wandb_setup.py:_flush():76] Configure stats pid to 16112
2023-04-19 09:46:05,444 INFO    Thread-264 (_run_job):16112 [wandb_setup.py:_flush():76] Loading settings from C:\Users\cosmi\.config\wandb\settings
2023-04-19 09:46:05,444 INFO    Thread-264 (_run_job):16112 [wandb_setup.py:_flush():76] Loading settings from C:\MyDocuments\Disertatie\segments\wandb_visualization\wandb\settings
2023-04-19 09:46:05,444 INFO    Thread-264 (_run_job):16112 [wandb_setup.py:_flush():76] Loading settings from environment variables: {'entity': 'cosminaionut', 'project': 'Defect-Detection-Sweep', 'root_dir': 'C:\\MyDocuments\\Disertatie\\segments\\wandb_visualization', 'run_id': 'e5vyt3gr', 'sweep_param_path': 'C:\\MyDocuments\\Disertatie\\segments\\wandb_visualization\\wandb\\sweep-uxdb9ain\\config-e5vyt3gr.yaml', 'sweep_id': 'uxdb9ain'}
2023-04-19 09:46:05,444 INFO    Thread-264 (_run_job):16112 [wandb_setup.py:_flush():76] Applying setup settings: {'_disable_service': False}
2023-04-19 09:46:05,444 INFO    Thread-264 (_run_job):16112 [wandb_setup.py:_flush():76] Inferring run settings from compute environment: {'program_relpath': 'sweeps_configuration.py', 'program': 'C:\\MyDocuments\\Disertatie\\segments\\wandb_visualization\\sweeps_configuration.py'}
2023-04-19 09:46:05,444 INFO    Thread-264 (_run_job):16112 [wandb_init.py:_log_setup():507] Logging user logs to C:\MyDocuments\Disertatie\segments\wandb_visualization\wandb\run-20230419_094605-e5vyt3gr\logs\debug.log
2023-04-19 09:46:05,444 INFO    Thread-264 (_run_job):16112 [wandb_init.py:_log_setup():508] Logging internal logs to C:\MyDocuments\Disertatie\segments\wandb_visualization\wandb\run-20230419_094605-e5vyt3gr\logs\debug-internal.log
2023-04-19 09:46:05,444 INFO    Thread-264 (_run_job):16112 [wandb_init.py:init():547] calling init triggers
2023-04-19 09:46:05,444 INFO    Thread-264 (_run_job):16112 [wandb_init.py:init():554] wandb.init called with sweep_config: {'batch_size': 16, 'epochs': 50, 'hidden_layer_size': [32, 64, 128, 256], 'learning_rate': 0.07547911436972558, 'monitor': 'val_loss', 'optimizer': 'adam', 'patience': 5}
config: {}
2023-04-19 09:46:05,444 INFO    Thread-264 (_run_job):16112 [wandb_init.py:init():595] starting backend
2023-04-19 09:46:05,444 INFO    Thread-264 (_run_job):16112 [wandb_init.py:init():599] setting up manager
2023-04-19 09:46:05,460 INFO    Thread-264 (_run_job):16112 [backend.py:_multiprocessing_setup():106] multiprocessing start_methods=spawn, using: spawn
2023-04-19 09:46:05,460 INFO    Thread-264 (_run_job):16112 [wandb_init.py:init():605] backend started and connected
2023-04-19 09:46:05,460 INFO    Thread-264 (_run_job):16112 [wandb_run.py:_config_callback():1285] config_cb None None {'batch_size': 16, 'epochs': 50, 'hidden_layer_size': [32, 64, 128, 256], 'learning_rate': 0.07547911436972558, 'monitor': 'val_loss', 'optimizer': 'adam', 'patience': 5}
2023-04-19 09:46:05,460 INFO    Thread-264 (_run_job):16112 [wandb_init.py:init():695] updated telemetry
2023-04-19 09:46:05,460 INFO    Thread-264 (_run_job):16112 [wandb_init.py:init():732] communicating run to backend with 60.0 second timeout
2023-04-19 09:46:06,013 INFO    Thread-264 (_run_job):16112 [wandb_run.py:_on_init():2176] communicating current version
2023-04-19 09:46:06,203 INFO    Thread-264 (_run_job):16112 [wandb_run.py:_on_init():2185] got version response 
2023-04-19 09:46:06,203 INFO    Thread-264 (_run_job):16112 [wandb_init.py:init():782] starting run threads in backend
2023-04-19 09:46:07,405 INFO    Thread-264 (_run_job):16112 [wandb_run.py:_console_start():2157] atexit reg
2023-04-19 09:46:07,405 INFO    Thread-264 (_run_job):16112 [wandb_run.py:_redirect():2012] redirect: SettingsConsole.WRAP_RAW
2023-04-19 09:46:07,405 INFO    Thread-264 (_run_job):16112 [wandb_run.py:_redirect():2077] Wrapping output streams.
2023-04-19 09:46:07,405 INFO    Thread-264 (_run_job):16112 [wandb_run.py:_redirect():2102] Redirects installed.
2023-04-19 09:46:07,405 INFO    Thread-264 (_run_job):16112 [wandb_init.py:init():824] run started, returning control to user process
2023-04-19 09:48:07,727 ERROR   Thread-6 (_heartbeat):16112 [internal_api.py:execute():288] 500 response executing GraphQL.
2023-04-19 09:48:07,727 ERROR   Thread-6 (_heartbeat):16112 [internal_api.py:execute():289] {"error":"driver: bad connection"}
2023-04-19 09:48:09,308 ERROR   Thread-6 (_heartbeat):16112 [internal_api.py:execute():288] 500 response executing GraphQL.
2023-04-19 09:48:09,308 ERROR   Thread-6 (_heartbeat):16112 [internal_api.py:execute():289] {"error":"driver: bad connection"}
2023-04-19 09:48:12,320 ERROR   Thread-6 (_heartbeat):16112 [internal_api.py:execute():288] 500 response executing GraphQL.
2023-04-19 09:48:12,320 ERROR   Thread-6 (_heartbeat):16112 [internal_api.py:execute():289] {"error":"driver: bad connection"}
2023-04-19 09:48:12,320 INFO    Thread-6 (_heartbeat):16112 [retry.py:__call__():172] Retry attempt failed:
Traceback (most recent call last):
  File "C:\Python310\lib\site-packages\wandb\sdk\lib\retry.py", line 131, in __call__
    result = self._call_fn(*args, **kwargs)
  File "C:\Python310\lib\site-packages\wandb\sdk\internal\internal_api.py", line 285, in execute
    return self.client.execute(*args, **kwargs)  # type: ignore
  File "C:\Python310\lib\site-packages\wandb\vendor\gql-0.2.0\wandb_gql\client.py", line 52, in execute
    result = self._get_result(document, *args, **kwargs)
  File "C:\Python310\lib\site-packages\wandb\vendor\gql-0.2.0\wandb_gql\client.py", line 60, in _get_result
    return self.transport.execute(document, *args, **kwargs)
  File "C:\Python310\lib\site-packages\wandb\sdk\lib\gql_request.py", line 56, in execute
    request.raise_for_status()
  File "C:\Python310\lib\site-packages\requests\models.py", line 1021, in raise_for_status
    raise HTTPError(http_error_msg, response=self)
requests.exceptions.HTTPError: 500 Server Error: Internal Server Error for url: https://api.wandb.ai/graphql
2023-04-19 09:48:19,382 ERROR   Thread-6 (_heartbeat):16112 [internal_api.py:execute():288] 500 response executing GraphQL.
2023-04-19 09:48:19,382 ERROR   Thread-6 (_heartbeat):16112 [internal_api.py:execute():289] {"error":"An internal error occurred. Please contact support."}
2023-04-19 09:48:29,827 ERROR   Thread-6 (_heartbeat):16112 [internal_api.py:execute():288] 500 response executing GraphQL.
2023-04-19 09:48:29,827 ERROR   Thread-6 (_heartbeat):16112 [internal_api.py:execute():289] {"errors":[{"message":"An internal error occurred. Please contact support.","path":["agentHeartbeat"]}],"data":{"agentHeartbeat":null}}
2023-04-19 09:48:39,354 INFO    Thread-264 (_run_job):16112 [wandb_run.py:_finish():1892] finishing run cosminaionut/Defect-Detection-Sweep/e5vyt3gr
2023-04-19 09:48:39,354 INFO    Thread-264 (_run_job):16112 [wandb_run.py:_atexit_cleanup():2126] got exitcode: 0
2023-04-19 09:48:39,354 INFO    Thread-264 (_run_job):16112 [wandb_run.py:_restore():2109] restore
2023-04-19 09:48:39,354 INFO    Thread-264 (_run_job):16112 [wandb_run.py:_restore():2115] restore done
2023-04-19 09:48:47,611 ERROR   Thread-6 (_heartbeat):16112 [internal_api.py:execute():288] 500 response executing GraphQL.
2023-04-19 09:48:47,611 ERROR   Thread-6 (_heartbeat):16112 [internal_api.py:execute():289] {"errors":[{"message":"An internal error occurred. Please contact support.","path":["agentHeartbeat"]}],"data":{"agentHeartbeat":null}}
2023-04-19 09:49:25,580 INFO    Thread-264 (_run_job):16112 [wandb_run.py:_footer_history_summary_info():3476] rendering history
2023-04-19 09:49:25,580 INFO    Thread-264 (_run_job):16112 [wandb_run.py:_footer_history_summary_info():3508] rendering summary
2023-04-19 09:49:25,580 INFO    Thread-264 (_run_job):16112 [wandb_run.py:_footer_sync_info():3434] logging synced files
