Traceback (most recent call last):
  File "C:\MyDocuments\Dizertatie\segments\wandb_visualization\no_overlap\test_mode_visualization.py", line 107, in <module>
    error = mean_squared_error(Y_test, y_pred)
  File "C:\MyDocuments\Dizertatie\segments\venv\lib\site-packages\tensorflow\python\util\traceback_utils.py", line 153, in error_handler
    raise e.with_traceback(filtered_tb) from None
  File "C:\MyDocuments\Dizertatie\segments\venv\lib\site-packages\keras\losses.py", line 1500, in mean_squared_error
    return backend.mean(tf.math.squared_difference(y_pred, y_true), axis=-1)
tensorflow.python.framework.errors_impl.InvalidArgumentError: {{function_node __wrapped__SquaredDifference_device_/job:localhost/replica:0/task:0/device:CPU:0}} Incompatible shapes: [20,1] vs. [9855,1] [Op:SquaredDifference]
Predicted pos:  [0.414] actual pos:  [0.414]
Predicted pos:  [0.414] actual pos:  [0.414]
Predicted pos:  [0.4132] actual pos:  [0.414]
Predicted pos:  [0.4168] actual pos:  [0.414]
Predicted pos:  [0.414] actual pos:  [0.414]
Predicted pos:  [0.414] actual pos:  [0.414]
Predicted pos:  [0.4296] actual pos:  [0.432]
Predicted pos:  [0.4304] actual pos:  [0.432]
Predicted pos:  [0.4292] actual pos:  [0.432]
Predicted pos:  [0.4272] actual pos:  [0.432]
Predicted pos:  [0.4248] actual pos:  [0.432]
Predicted pos:  [0.4276] actual pos:  [0.432]
Predicted pos:  [0.4284] actual pos:  [0.432]
Predicted pos:  [0.4844] actual pos:  [0.468]
Predicted pos:  [0.5108] actual pos:  [0.468]
Predicted pos:  [0.4936] actual pos:  [0.468]
Predicted pos:  [0.496] actual pos:  [0.468]
Predicted pos:  [0.4948] actual pos:  [0.468]
Predicted pos:  [0.4964] actual pos:  [0.468]
Predicted pos:  [0.4944] actual pos:  [0.468]