2023-04-18 20:51:36,162 INFO    StreamThr :18752 [internal.py:wandb_internal():86] W&B internal server running at pid: 18752, started at: 2023-04-18 20:51:36.162949
2023-04-18 20:51:36,170 DEBUG   HandlerThread:18752 [handler.py:handle_request():144] handle_request: status
2023-04-18 20:51:36,193 INFO    WriterThread:18752 [datastore.py:open_for_write():85] open: C:\MyDocuments\Disertatie\segments\wandb_visualization\wandb\run-20230418_205136-dgfh6j54\run-dgfh6j54.wandb
2023-04-18 20:51:36,202 DEBUG   SenderThread:18752 [sender.py:send():375] send: header
2023-04-18 20:51:36,202 DEBUG   SenderThread:18752 [sender.py:send():375] send: run
2023-04-18 20:51:41,245 DEBUG   HandlerThread:18752 [handler.py:handle_request():144] handle_request: keepalive
2023-04-18 20:51:46,280 DEBUG   HandlerThread:18752 [handler.py:handle_request():144] handle_request: keepalive
2023-04-18 20:51:51,296 DEBUG   HandlerThread:18752 [handler.py:handle_request():144] handle_request: keepalive
2023-04-18 20:51:56,321 DEBUG   HandlerThread:18752 [handler.py:handle_request():144] handle_request: keepalive
2023-04-18 20:52:01,349 DEBUG   HandlerThread:18752 [handler.py:handle_request():144] handle_request: keepalive
2023-04-18 20:52:06,396 DEBUG   HandlerThread:18752 [handler.py:handle_request():144] handle_request: keepalive
2023-04-18 20:52:11,425 DEBUG   HandlerThread:18752 [handler.py:handle_request():144] handle_request: keepalive
2023-04-18 20:52:11,803 INFO    SenderThread:18752 [retry.py:__call__():172] Retry attempt failed:
Traceback (most recent call last):
  File "C:\Python310\lib\site-packages\urllib3\connectionpool.py", line 449, in _make_request
    six.raise_from(e, None)
  File "<string>", line 3, in raise_from
  File "C:\Python310\lib\site-packages\urllib3\connectionpool.py", line 444, in _make_request
    httplib_response = conn.getresponse()
  File "C:\Python310\lib\http\client.py", line 1374, in getresponse
    response.begin()
  File "C:\Python310\lib\http\client.py", line 318, in begin
    version, status, reason = self._read_status()
  File "C:\Python310\lib\http\client.py", line 279, in _read_status
    line = str(self.fp.readline(_MAXLINE + 1), "iso-8859-1")
  File "C:\Python310\lib\socket.py", line 705, in readinto
    return self._sock.recv_into(b)
  File "C:\Python310\lib\ssl.py", line 1274, in recv_into
    return self.read(nbytes, buffer)
  File "C:\Python310\lib\ssl.py", line 1130, in read
    return self._sslobj.read(len, buffer)
TimeoutError: The read operation timed out

During handling of the above exception, another exception occurred:

Traceback (most recent call last):
  File "C:\Python310\lib\site-packages\requests\adapters.py", line 489, in send
    resp = conn.urlopen(
  File "C:\Python310\lib\site-packages\urllib3\connectionpool.py", line 787, in urlopen
    retries = retries.increment(
  File "C:\Python310\lib\site-packages\urllib3\util\retry.py", line 550, in increment
    raise six.reraise(type(error), error, _stacktrace)
  File "C:\Python310\lib\site-packages\urllib3\packages\six.py", line 770, in reraise
    raise value
  File "C:\Python310\lib\site-packages\urllib3\connectionpool.py", line 703, in urlopen
    httplib_response = self._make_request(
  File "C:\Python310\lib\site-packages\urllib3\connectionpool.py", line 451, in _make_request
    self._raise_timeout(err=e, url=url, timeout_value=read_timeout)
  File "C:\Python310\lib\site-packages\urllib3\connectionpool.py", line 340, in _raise_timeout
    raise ReadTimeoutError(
urllib3.exceptions.ReadTimeoutError: HTTPSConnectionPool(host='api.wandb.ai', port=443): Read timed out. (read timeout=10)

During handling of the above exception, another exception occurred:

Traceback (most recent call last):
  File "C:\Python310\lib\site-packages\wandb\sdk\lib\retry.py", line 131, in __call__
    result = self._call_fn(*args, **kwargs)
  File "C:\Python310\lib\site-packages\wandb\sdk\internal\internal_api.py", line 285, in execute
    return self.client.execute(*args, **kwargs)  # type: ignore
  File "C:\Python310\lib\site-packages\wandb\vendor\gql-0.2.0\wandb_gql\client.py", line 52, in execute
    result = self._get_result(document, *args, **kwargs)
  File "C:\Python310\lib\site-packages\wandb\vendor\gql-0.2.0\wandb_gql\client.py", line 60, in _get_result
    return self.transport.execute(document, *args, **kwargs)
  File "C:\Python310\lib\site-packages\wandb\sdk\lib\gql_request.py", line 55, in execute
    request = self.session.post(self.url, **post_args)
  File "C:\Python310\lib\site-packages\requests\sessions.py", line 635, in post
    return self.request("POST", url, data=data, json=json, **kwargs)
  File "C:\Python310\lib\site-packages\requests\sessions.py", line 587, in request
    resp = self.send(prep, **send_kwargs)
  File "C:\Python310\lib\site-packages\requests\sessions.py", line 701, in send
    r = adapter.send(request, **kwargs)
  File "C:\Python310\lib\site-packages\requests\adapters.py", line 578, in send
    raise ReadTimeout(e, request=request)
requests.exceptions.ReadTimeout: HTTPSConnectionPool(host='api.wandb.ai', port=443): Read timed out. (read timeout=10)
2023-04-18 20:52:16,461 DEBUG   HandlerThread:18752 [handler.py:handle_request():144] handle_request: keepalive
2023-04-18 20:52:21,509 DEBUG   HandlerThread:18752 [handler.py:handle_request():144] handle_request: keepalive
2023-04-18 20:52:26,557 DEBUG   HandlerThread:18752 [handler.py:handle_request():144] handle_request: keepalive
2023-04-18 20:52:31,595 DEBUG   HandlerThread:18752 [handler.py:handle_request():144] handle_request: keepalive
2023-04-18 20:52:36,636 DEBUG   HandlerThread:18752 [handler.py:handle_request():144] handle_request: cancel
2023-04-18 20:52:36,638 DEBUG   HandlerThread:18752 [handler.py:handle_request():144] handle_request: cancel
2023-04-18 20:52:37,513 INFO    SenderThread:18752 [dir_watcher.py:__init__():219] watching files in: C:\MyDocuments\Disertatie\segments\wandb_visualization\wandb\run-20230418_205136-dgfh6j54\files
2023-04-18 20:52:37,513 INFO    SenderThread:18752 [sender.py:_start_run_threads():1124] run started: dgfh6j54 with start time 1681840296.170949
2023-04-18 20:52:37,513 DEBUG   HandlerThread:18752 [handler.py:handle_request():144] handle_request: status_report
2023-04-18 20:52:42,564 DEBUG   HandlerThread:18752 [handler.py:handle_request():144] handle_request: status_report
2023-04-18 20:52:46,768 DEBUG   HandlerThread:18752 [handler.py:handle_request():144] handle_request: shutdown
2023-04-18 20:52:46,768 INFO    HandlerThread:18752 [handler.py:finish():845] shutting down handler
2023-04-18 20:52:47,580 INFO    WriterThread:18752 [datastore.py:close():298] close: C:\MyDocuments\Disertatie\segments\wandb_visualization\wandb\run-20230418_205136-dgfh6j54\run-dgfh6j54.wandb
2023-04-18 20:52:47,580 INFO    SenderThread:18752 [sender.py:finish():1550] shutting down sender
2023-04-18 20:52:47,580 INFO    SenderThread:18752 [dir_watcher.py:finish():365] shutting down directory watcher
2023-04-18 20:52:48,583 INFO    SenderThread:18752 [dir_watcher.py:finish():395] scan: C:\MyDocuments\Disertatie\segments\wandb_visualization\wandb\run-20230418_205136-dgfh6j54\files
2023-04-18 20:52:48,583 INFO    SenderThread:18752 [dir_watcher.py:finish():409] scan save: C:\MyDocuments\Disertatie\segments\wandb_visualization\wandb\run-20230418_205136-dgfh6j54\files\config.yaml config.yaml
2023-04-18 20:52:48,583 INFO    SenderThread:18752 [file_pusher.py:finish():168] shutting down file pusher
2023-04-18 20:52:48,583 INFO    SenderThread:18752 [file_pusher.py:join():173] waiting for file pusher
2023-04-18 20:52:49,301 INFO    wandb-upload_0:18752 [upload_job.py:push():137] Uploaded file C:\MyDocuments\Disertatie\segments\wandb_visualization\wandb\run-20230418_205136-dgfh6j54\files\config.yaml
