[[0.00086654 0.00086654 0.00086654 ... 0.00086654 0.00086654 0.00086654]
 [0.00119113 0.00119113 0.00119113 ... 0.00119113 0.00119113 0.00119113]
 [0.00214098 0.00214098 0.00214098 ... 0.00214098 0.00214098 0.00214098]
 ...
 [0.03716586 0.0253569  0.01678278 ... 0.00258239 0.0016026  0.00215171]
 [0.0462074  0.03139693 0.02064352 ... 0.00283378 0.00160496 0.00229364]
 [0.05900354 0.03994516 0.02610747 ... 0.00318957 0.0016083  0.0024945 ]]
[[0.  ]
 [0.  ]
 [0.  ]
 ...
 [0.05]
 [0.05]
 [0.05]]
(1518, 8)
(1518, 1)
(380, 8)
(380, 1)
Epoch 1/300
WARNING:tensorflow:Please fix your imports. Module tensorflow.python.training.tracking.data_structures has been moved to tensorflow.python.trackable.data_structures. The old module will be deleted in version 2.11.
wandb: WARNING The save_model argument by default saves the model in the HDF5 format that cannot save custom objects like subclassed models and custom layers. This behavior will be deprecated in a future release in favor of the SavedModel format. Meanwhile, the HDF5 model is saved as W&B files and the SavedModel as W&B Artifacts.
WARNING:tensorflow:Callback method `on_train_batch_end` is slow compared to the batch time (batch time: 0.0020s vs `on_train_batch_end` time: 0.0032s). Check your callbacks.
14/16 [=========================>....] - ETA: 0s - loss: -422.4879 - mae: 1.5060 - mse: 3.3609
wandb: ERROR Can't save model in the h5py format. The model will be saved as as an W&B Artifact in the 'tf' format.
Traceback (most recent call last):
  File "C:\MyDocuments\Disertatie\segments\wandb_visualization\overlap\wrapper_test_and_train.py", line 358, in <module>
    train_ANN()
  File "C:\MyDocuments\Disertatie\segments\wandb_visualization\overlap\wrapper_test_and_train.py", line 216, in train_ANN
    train_models_and_save(n_members,data,test_size,train_group, epochs, batch_size, learning_rate,optimizer,hidden_layer_size,patience,monitor)
  File "C:\MyDocuments\Disertatie\segments\wandb_visualization\overlap\test_and_train.py", line 33, in train_models_and_save
    network, history = train_model_sweep(build_nn_sweep_BNN(optimizer, learning_rate, hidden_layer_size,sample_size), x_train,
  File "C:\MyDocuments\Disertatie\segments\model_training\overlap\model_generating_RNN.py", line 122, in train_model_sweep
    history = network.fit(x_train, y_train, epochs=epochs, batch_size = batch_size, validation_data=(x_test, y_test),
  File "C:\Users\cosmi\AppData\Roaming\Python\Python39\site-packages\wandb\integration\keras\keras.py", line 174, in new_v2
    return old_v2(*args, **kwargs)
  File "C:\Users\cosmi\AppData\Roaming\Python\Python39\site-packages\wandb\integration\keras\keras.py", line 174, in new_v2
    return old_v2(*args, **kwargs)
  File "C:\Users\cosmi\AppData\Roaming\Python\Python39\site-packages\wandb\integration\keras\keras.py", line 174, in new_v2
    return old_v2(*args, **kwargs)
  File "C:\Users\cosmi\anaconda3\envs\tf2.12\lib\site-packages\keras\utils\traceback_utils.py", line 70, in error_handler
    raise e.with_traceback(filtered_tb) from None
  File "C:\Users\cosmi\AppData\Roaming\Python\Python39\site-packages\wandb\integration\keras\keras.py", line 630, in on_epoch_end
    self._save_model_as_artifact(epoch)
  File "C:\Users\cosmi\AppData\Roaming\Python\Python39\site-packages\wandb\integration\keras\keras.py", line 1032, in _save_model_as_artifact
    self.model.save(self.filepath[:-3], overwrite=True, save_format="tf")
  File "C:\Users\cosmi\anaconda3\envs\tf2.12\lib\contextlib.py", line 126, in __exit__
    next(self.gen)
  File "C:\Users\cosmi\anaconda3\envs\tf2.12\lib\site-packages\tensorflow_probability\python\layers\distribution_layer.py", line 224, in __call__
    distribution, _ = super(DistributionLambda, self).__call__(
tensorflow.python.framework.errors_impl.OperatorNotAllowedInGraphError: Iterating over a symbolic `tf.Tensor` is not allowed: AutoGraph did convert this function. This might indicate you are trying to use an unsupported feature.