2023-04-19 09:51:21,062 INFO    Thread-655 (_run_job):16112 [wandb_setup.py:_flush():76] Configure stats pid to 16112
2023-04-19 09:51:21,062 INFO    Thread-655 (_run_job):16112 [wandb_setup.py:_flush():76] Loading settings from C:\Users\cosmi\.config\wandb\settings
2023-04-19 09:51:21,062 INFO    Thread-655 (_run_job):16112 [wandb_setup.py:_flush():76] Loading settings from C:\MyDocuments\Disertatie\segments\wandb_visualization\wandb\settings
2023-04-19 09:51:21,062 INFO    Thread-655 (_run_job):16112 [wandb_setup.py:_flush():76] Loading settings from environment variables: {'entity': 'cosminaionut', 'project': 'Defect-Detection-Sweep', 'root_dir': 'C:\\MyDocuments\\Disertatie\\segments\\wandb_visualization', 'run_id': '68izqttl', 'sweep_param_path': 'C:\\MyDocuments\\Disertatie\\segments\\wandb_visualization\\wandb\\sweep-uxdb9ain\\config-68izqttl.yaml', 'sweep_id': 'uxdb9ain'}
2023-04-19 09:51:21,062 INFO    Thread-655 (_run_job):16112 [wandb_setup.py:_flush():76] Applying setup settings: {'_disable_service': False}
2023-04-19 09:51:21,062 INFO    Thread-655 (_run_job):16112 [wandb_setup.py:_flush():76] Inferring run settings from compute environment: {'program_relpath': 'sweeps_configuration.py', 'program': 'C:\\MyDocuments\\Disertatie\\segments\\wandb_visualization\\sweeps_configuration.py'}
2023-04-19 09:51:21,062 INFO    Thread-655 (_run_job):16112 [wandb_init.py:_log_setup():507] Logging user logs to C:\MyDocuments\Disertatie\segments\wandb_visualization\wandb\run-20230419_095121-68izqttl\logs\debug.log
2023-04-19 09:51:21,062 INFO    Thread-655 (_run_job):16112 [wandb_init.py:_log_setup():508] Logging internal logs to C:\MyDocuments\Disertatie\segments\wandb_visualization\wandb\run-20230419_095121-68izqttl\logs\debug-internal.log
2023-04-19 09:51:21,062 INFO    Thread-655 (_run_job):16112 [wandb_init.py:init():547] calling init triggers
2023-04-19 09:51:21,062 INFO    Thread-655 (_run_job):16112 [wandb_init.py:init():554] wandb.init called with sweep_config: {'batch_size': 16, 'epochs': 200, 'hidden_layer_size': [32, 64, 128], 'learning_rate': 0.06300249720927638, 'monitor': 'val_loss', 'optimizer': 'sgd', 'patience': 10}
config: {}
2023-04-19 09:51:21,078 INFO    Thread-655 (_run_job):16112 [wandb_init.py:init():595] starting backend
2023-04-19 09:51:21,078 INFO    Thread-655 (_run_job):16112 [wandb_init.py:init():599] setting up manager
2023-04-19 09:51:21,078 INFO    Thread-655 (_run_job):16112 [backend.py:_multiprocessing_setup():106] multiprocessing start_methods=spawn, using: spawn
2023-04-19 09:51:21,078 INFO    Thread-655 (_run_job):16112 [wandb_init.py:init():605] backend started and connected
2023-04-19 09:51:21,093 INFO    Thread-655 (_run_job):16112 [wandb_run.py:_config_callback():1285] config_cb None None {'batch_size': 16, 'epochs': 200, 'hidden_layer_size': [32, 64, 128], 'learning_rate': 0.06300249720927638, 'monitor': 'val_loss', 'optimizer': 'sgd', 'patience': 10}
2023-04-19 09:51:21,093 INFO    Thread-655 (_run_job):16112 [wandb_init.py:init():695] updated telemetry
2023-04-19 09:51:21,093 INFO    Thread-655 (_run_job):16112 [wandb_init.py:init():732] communicating run to backend with 60.0 second timeout
2023-04-19 09:51:21,610 INFO    Thread-655 (_run_job):16112 [wandb_run.py:_on_init():2176] communicating current version
2023-04-19 09:51:21,797 INFO    Thread-655 (_run_job):16112 [wandb_run.py:_on_init():2185] got version response 
2023-04-19 09:51:21,797 INFO    Thread-655 (_run_job):16112 [wandb_init.py:init():782] starting run threads in backend
2023-04-19 09:51:22,307 INFO    Thread-655 (_run_job):16112 [wandb_run.py:_console_start():2157] atexit reg
2023-04-19 09:51:22,307 INFO    Thread-655 (_run_job):16112 [wandb_run.py:_redirect():2012] redirect: SettingsConsole.WRAP_RAW
2023-04-19 09:51:22,307 INFO    Thread-655 (_run_job):16112 [wandb_run.py:_redirect():2077] Wrapping output streams.
2023-04-19 09:51:22,307 INFO    Thread-655 (_run_job):16112 [wandb_run.py:_redirect():2102] Redirects installed.
2023-04-19 09:51:22,307 INFO    Thread-655 (_run_job):16112 [wandb_init.py:init():824] run started, returning control to user process
2023-04-19 09:52:25,240 ERROR   Thread-6 (_heartbeat):16112 [internal_api.py:execute():288] 502 response executing GraphQL.
2023-04-19 09:52:25,240 ERROR   Thread-6 (_heartbeat):16112 [internal_api.py:execute():289] 
<html><head>
<meta http-equiv="content-type" content="text/html;charset=utf-8">
<title>502 Server Error</title>
</head>
<body text=#000000 bgcolor=#ffffff>
<h1>Error: Server Error</h1>
<h2>The server encountered a temporary error and could not complete your request.<p>Please try again in 30 seconds.</h2>
<h2></h2>
</body></html>

2023-04-19 09:52:35,547 ERROR   Thread-6 (_heartbeat):16112 [internal_api.py:execute():288] 502 response executing GraphQL.
2023-04-19 09:52:35,547 ERROR   Thread-6 (_heartbeat):16112 [internal_api.py:execute():289] 
<html><head>
<meta http-equiv="content-type" content="text/html;charset=utf-8">
<title>502 Server Error</title>
</head>
<body text=#000000 bgcolor=#ffffff>
<h1>Error: Server Error</h1>
<h2>The server encountered a temporary error and could not complete your request.<p>Please try again in 30 seconds.</h2>
<h2></h2>
</body></html>

2023-04-19 09:52:46,902 ERROR   Thread-6 (_heartbeat):16112 [internal_api.py:execute():288] 502 response executing GraphQL.
2023-04-19 09:52:46,902 ERROR   Thread-6 (_heartbeat):16112 [internal_api.py:execute():289] 
<html><head>
<meta http-equiv="content-type" content="text/html;charset=utf-8">
<title>502 Server Error</title>
</head>
<body text=#000000 bgcolor=#ffffff>
<h1>Error: Server Error</h1>
<h2>The server encountered a temporary error and could not complete your request.<p>Please try again in 30 seconds.</h2>
<h2></h2>
</body></html>

2023-04-19 09:52:46,902 INFO    Thread-6 (_heartbeat):16112 [retry.py:__call__():172] Retry attempt failed:
Traceback (most recent call last):
  File "C:\Python310\lib\site-packages\wandb\sdk\lib\retry.py", line 131, in __call__
    result = self._call_fn(*args, **kwargs)
  File "C:\Python310\lib\site-packages\wandb\sdk\internal\internal_api.py", line 285, in execute
    return self.client.execute(*args, **kwargs)  # type: ignore
  File "C:\Python310\lib\site-packages\wandb\vendor\gql-0.2.0\wandb_gql\client.py", line 52, in execute
    result = self._get_result(document, *args, **kwargs)
  File "C:\Python310\lib\site-packages\wandb\vendor\gql-0.2.0\wandb_gql\client.py", line 60, in _get_result
    return self.transport.execute(document, *args, **kwargs)
  File "C:\Python310\lib\site-packages\wandb\sdk\lib\gql_request.py", line 56, in execute
    request.raise_for_status()
  File "C:\Python310\lib\site-packages\requests\models.py", line 1021, in raise_for_status
    raise HTTPError(http_error_msg, response=self)
requests.exceptions.HTTPError: 502 Server Error: Bad Gateway for url: https://api.wandb.ai/graphql
2023-04-19 09:53:00,543 ERROR   Thread-6 (_heartbeat):16112 [internal_api.py:execute():288] 502 response executing GraphQL.
2023-04-19 09:53:00,543 ERROR   Thread-6 (_heartbeat):16112 [internal_api.py:execute():289] 
<html><head>
<meta http-equiv="content-type" content="text/html;charset=utf-8">
<title>502 Server Error</title>
</head>
<body text=#000000 bgcolor=#ffffff>
<h1>Error: Server Error</h1>
<h2>The server encountered a temporary error and could not complete your request.<p>Please try again in 30 seconds.</h2>
<h2></h2>
</body></html>

2023-04-19 09:53:18,106 ERROR   Thread-6 (_heartbeat):16112 [internal_api.py:execute():288] 502 response executing GraphQL.
2023-04-19 09:53:18,106 ERROR   Thread-6 (_heartbeat):16112 [internal_api.py:execute():289] 
<html><head>
<meta http-equiv="content-type" content="text/html;charset=utf-8">
<title>502 Server Error</title>
</head>
<body text=#000000 bgcolor=#ffffff>
<h1>Error: Server Error</h1>
<h2>The server encountered a temporary error and could not complete your request.<p>Please try again in 30 seconds.</h2>
<h2></h2>
</body></html>

2023-04-19 09:53:45,749 ERROR   Thread-6 (_heartbeat):16112 [internal_api.py:execute():288] 502 response executing GraphQL.
2023-04-19 09:53:45,749 ERROR   Thread-6 (_heartbeat):16112 [internal_api.py:execute():289] 
<html><head>
<meta http-equiv="content-type" content="text/html;charset=utf-8">
<title>502 Server Error</title>
</head>
<body text=#000000 bgcolor=#ffffff>
<h1>Error: Server Error</h1>
<h2>The server encountered a temporary error and could not complete your request.<p>Please try again in 30 seconds.</h2>
<h2></h2>
</body></html>

2023-04-19 09:54:31,483 ERROR   Thread-6 (_heartbeat):16112 [internal_api.py:execute():288] 502 response executing GraphQL.
2023-04-19 09:54:31,483 ERROR   Thread-6 (_heartbeat):16112 [internal_api.py:execute():289] 
<html><head>
<meta http-equiv="content-type" content="text/html;charset=utf-8">
<title>502 Server Error</title>
</head>
<body text=#000000 bgcolor=#ffffff>
<h1>Error: Server Error</h1>
<h2>The server encountered a temporary error and could not complete your request.<p>Please try again in 30 seconds.</h2>
<h2></h2>
</body></html>

2023-04-19 09:56:12,161 ERROR   Thread-6 (_heartbeat):16112 [internal_api.py:execute():288] 500 response executing GraphQL.
2023-04-19 09:56:12,161 ERROR   Thread-6 (_heartbeat):16112 [internal_api.py:execute():289] {"error":"driver: bad connection"}
2023-04-19 09:56:13,609 ERROR   Thread-6 (_heartbeat):16112 [internal_api.py:execute():288] 500 response executing GraphQL.
2023-04-19 09:56:13,609 ERROR   Thread-6 (_heartbeat):16112 [internal_api.py:execute():289] {"error":"driver: bad connection"}
2023-04-19 09:56:16,894 ERROR   Thread-6 (_heartbeat):16112 [internal_api.py:execute():288] 500 response executing GraphQL.
2023-04-19 09:56:16,894 ERROR   Thread-6 (_heartbeat):16112 [internal_api.py:execute():289] {"error":"An internal error occurred. Please contact support."}
2023-04-19 09:56:16,910 INFO    Thread-6 (_heartbeat):16112 [retry.py:__call__():172] Retry attempt failed:
Traceback (most recent call last):
  File "C:\Python310\lib\site-packages\wandb\sdk\lib\retry.py", line 131, in __call__
    result = self._call_fn(*args, **kwargs)
  File "C:\Python310\lib\site-packages\wandb\sdk\internal\internal_api.py", line 285, in execute
    return self.client.execute(*args, **kwargs)  # type: ignore
  File "C:\Python310\lib\site-packages\wandb\vendor\gql-0.2.0\wandb_gql\client.py", line 52, in execute
    result = self._get_result(document, *args, **kwargs)
  File "C:\Python310\lib\site-packages\wandb\vendor\gql-0.2.0\wandb_gql\client.py", line 60, in _get_result
    return self.transport.execute(document, *args, **kwargs)
  File "C:\Python310\lib\site-packages\wandb\sdk\lib\gql_request.py", line 56, in execute
    request.raise_for_status()
  File "C:\Python310\lib\site-packages\requests\models.py", line 1021, in raise_for_status
    raise HTTPError(http_error_msg, response=self)
requests.exceptions.HTTPError: 500 Server Error: Internal Server Error for url: https://api.wandb.ai/graphql
2023-04-19 09:56:21,853 ERROR   Thread-6 (_heartbeat):16112 [internal_api.py:execute():288] 500 response executing GraphQL.
2023-04-19 09:56:21,853 ERROR   Thread-6 (_heartbeat):16112 [internal_api.py:execute():289] {"error":"An internal error occurred. Please contact support."}
2023-04-19 09:56:31,528 ERROR   Thread-6 (_heartbeat):16112 [internal_api.py:execute():288] 500 response executing GraphQL.
2023-04-19 09:56:31,528 ERROR   Thread-6 (_heartbeat):16112 [internal_api.py:execute():289] {"error":"An internal error occurred. Please contact support."}
2023-04-19 09:56:55,079 ERROR   Thread-6 (_heartbeat):16112 [internal_api.py:execute():288] 500 response executing GraphQL.
2023-04-19 09:56:55,079 ERROR   Thread-6 (_heartbeat):16112 [internal_api.py:execute():289] {"error":"An internal error occurred. Please contact support."}
2023-04-19 09:57:13,259 ERROR   Thread-6 (_heartbeat):16112 [internal_api.py:execute():288] 500 response executing GraphQL.
2023-04-19 09:57:13,259 ERROR   Thread-6 (_heartbeat):16112 [internal_api.py:execute():289] {"error":"An internal error occurred. Please contact support."}
2023-04-19 09:57:14,671 ERROR   Thread-6 (_heartbeat):16112 [internal_api.py:execute():288] 500 response executing GraphQL.
2023-04-19 09:57:14,671 ERROR   Thread-6 (_heartbeat):16112 [internal_api.py:execute():289] {"errors":[{"message":"An internal error occurred. Please contact support.","path":["agentHeartbeat"]}],"data":{"agentHeartbeat":null}}
2023-04-19 09:59:54,119 INFO    Thread-655 (_run_job):16112 [wandb_run.py:_finish():1892] finishing run cosminaionut/Defect-Detection-Sweep/68izqttl
2023-04-19 09:59:54,119 INFO    Thread-655 (_run_job):16112 [wandb_run.py:_atexit_cleanup():2126] got exitcode: 0
2023-04-19 09:59:54,119 INFO    Thread-655 (_run_job):16112 [wandb_run.py:_restore():2109] restore
2023-04-19 09:59:54,119 INFO    Thread-655 (_run_job):16112 [wandb_run.py:_restore():2115] restore done
2023-04-19 10:00:00,461 INFO    Thread-655 (_run_job):16112 [wandb_run.py:_footer_history_summary_info():3476] rendering history
2023-04-19 10:00:00,461 INFO    Thread-655 (_run_job):16112 [wandb_run.py:_footer_history_summary_info():3508] rendering summary
2023-04-19 10:00:00,461 INFO    Thread-655 (_run_job):16112 [wandb_run.py:_footer_sync_info():3434] logging synced files
